2022-03-18 18:30:44 ERROR 400 response executing GraphQL.
2022-03-18 18:30:44 ERROR {"errors":[{"message":"Invalid sweep config: invalid hyperparameter configuration: learning_rate","path":["upsertSweep"]}],"data":{"upsertSweep":null}}
2022-03-18 18:30:44 ERROR Traceback (most recent call last):
  File "/home/kevinteng/envs/tfenv/lib/python3.6/site-packages/wandb/sdk/lib/retry.py", line 102, in __call__
    result = self._call_fn(*args, **kwargs)
  File "/home/kevinteng/envs/tfenv/lib/python3.6/site-packages/wandb/sdk/internal/internal_api.py", line 146, in execute
    six.reraise(*sys.exc_info())
  File "/home/kevinteng/envs/tfenv/lib/python3.6/site-packages/six.py", line 719, in reraise
    raise value
  File "/home/kevinteng/envs/tfenv/lib/python3.6/site-packages/wandb/sdk/internal/internal_api.py", line 140, in execute
    return self.client.execute(*args, **kwargs)
  File "/home/kevinteng/envs/tfenv/lib/python3.6/site-packages/wandb/vendor/gql-0.2.0/wandb_gql/client.py", line 52, in execute
    result = self._get_result(document, *args, **kwargs)
  File "/home/kevinteng/envs/tfenv/lib/python3.6/site-packages/wandb/vendor/gql-0.2.0/wandb_gql/client.py", line 60, in _get_result
    return self.transport.execute(document, *args, **kwargs)
  File "/home/kevinteng/envs/tfenv/lib/python3.6/site-packages/wandb/vendor/gql-0.2.0/wandb_gql/transport/requests.py", line 39, in execute
    request.raise_for_status()
  File "/home/kevinteng/envs/tfenv/lib/python3.6/site-packages/requests/models.py", line 943, in raise_for_status
    raise HTTPError(http_error_msg, response=self)
requests.exceptions.HTTPError: 400 Client Error: Bad Request for url: https://api.wandb.ai/graphql

During handling of the above exception, another exception occurred:

Traceback (most recent call last):
  File "/home/kevinteng/envs/tfenv/lib/python3.6/site-packages/wandb/apis/normalize.py", line 24, in wrapper
    return func(*args, **kwargs)
  File "/home/kevinteng/envs/tfenv/lib/python3.6/site-packages/wandb/sdk/internal/internal_api.py", line 1887, in upsert_sweep
    raise (e)
  File "/home/kevinteng/envs/tfenv/lib/python3.6/site-packages/wandb/sdk/internal/internal_api.py", line 1884, in upsert_sweep
    check_retry_fn=no_retry_4xx,
  File "/home/kevinteng/envs/tfenv/lib/python3.6/site-packages/wandb/sdk/lib/retry.py", line 118, in __call__
    if not check_retry_fn(e):
  File "/home/kevinteng/envs/tfenv/lib/python3.6/site-packages/wandb/sdk/internal/internal_api.py", line 1864, in no_retry_4xx
    raise UsageError(body["errors"][0]["message"])
wandb.errors.UsageError: Invalid sweep config: invalid hyperparameter configuration: learning_rate

During handling of the above exception, another exception occurred:

Traceback (most recent call last):
  File "/home/kevinteng/envs/tfenv/lib/python3.6/site-packages/wandb/cli/cli.py", line 86, in wrapper
    return func(*args, **kwargs)
  File "/home/kevinteng/envs/tfenv/lib/python3.6/site-packages/wandb/cli/cli.py", line 858, in sweep
    config, project=project, entity=entity, obj_id=sweep_obj_id
  File "/home/kevinteng/envs/tfenv/lib/python3.6/site-packages/wandb/apis/internal.py", line 99, in upsert_sweep
    return self.api.upsert_sweep(*args, **kwargs)
  File "/home/kevinteng/envs/tfenv/lib/python3.6/site-packages/wandb/apis/normalize.py", line 62, in wrapper
    six.reraise(CommError, CommError(message, err), sys.exc_info()[2])
  File "/home/kevinteng/envs/tfenv/lib/python3.6/site-packages/six.py", line 718, in reraise
    raise value.with_traceback(tb)
  File "/home/kevinteng/envs/tfenv/lib/python3.6/site-packages/wandb/apis/normalize.py", line 24, in wrapper
    return func(*args, **kwargs)
  File "/home/kevinteng/envs/tfenv/lib/python3.6/site-packages/wandb/sdk/internal/internal_api.py", line 1887, in upsert_sweep
    raise (e)
  File "/home/kevinteng/envs/tfenv/lib/python3.6/site-packages/wandb/sdk/internal/internal_api.py", line 1884, in upsert_sweep
    check_retry_fn=no_retry_4xx,
  File "/home/kevinteng/envs/tfenv/lib/python3.6/site-packages/wandb/sdk/lib/retry.py", line 118, in __call__
    if not check_retry_fn(e):
  File "/home/kevinteng/envs/tfenv/lib/python3.6/site-packages/wandb/sdk/internal/internal_api.py", line 1864, in no_retry_4xx
    raise UsageError(body["errors"][0]["message"])
wandb.errors.CommError: Invalid sweep config: invalid hyperparameter configuration: learning_rate

2022-03-18 18:32:58 ERROR 400 response executing GraphQL.
2022-03-18 18:32:58 ERROR {"errors":[{"message":"Invalid sweep config: invalid hyperparameter configuration: learning_rate","path":["upsertSweep"]}],"data":{"upsertSweep":null}}
2022-03-18 18:32:58 ERROR Traceback (most recent call last):
  File "/home/kevinteng/envs/tfenv/lib/python3.6/site-packages/wandb/sdk/lib/retry.py", line 102, in __call__
    result = self._call_fn(*args, **kwargs)
  File "/home/kevinteng/envs/tfenv/lib/python3.6/site-packages/wandb/sdk/internal/internal_api.py", line 146, in execute
    six.reraise(*sys.exc_info())
  File "/home/kevinteng/envs/tfenv/lib/python3.6/site-packages/six.py", line 719, in reraise
    raise value
  File "/home/kevinteng/envs/tfenv/lib/python3.6/site-packages/wandb/sdk/internal/internal_api.py", line 140, in execute
    return self.client.execute(*args, **kwargs)
  File "/home/kevinteng/envs/tfenv/lib/python3.6/site-packages/wandb/vendor/gql-0.2.0/wandb_gql/client.py", line 52, in execute
    result = self._get_result(document, *args, **kwargs)
  File "/home/kevinteng/envs/tfenv/lib/python3.6/site-packages/wandb/vendor/gql-0.2.0/wandb_gql/client.py", line 60, in _get_result
    return self.transport.execute(document, *args, **kwargs)
  File "/home/kevinteng/envs/tfenv/lib/python3.6/site-packages/wandb/vendor/gql-0.2.0/wandb_gql/transport/requests.py", line 39, in execute
    request.raise_for_status()
  File "/home/kevinteng/envs/tfenv/lib/python3.6/site-packages/requests/models.py", line 943, in raise_for_status
    raise HTTPError(http_error_msg, response=self)
requests.exceptions.HTTPError: 400 Client Error: Bad Request for url: https://api.wandb.ai/graphql

During handling of the above exception, another exception occurred:

Traceback (most recent call last):
  File "/home/kevinteng/envs/tfenv/lib/python3.6/site-packages/wandb/apis/normalize.py", line 24, in wrapper
    return func(*args, **kwargs)
  File "/home/kevinteng/envs/tfenv/lib/python3.6/site-packages/wandb/sdk/internal/internal_api.py", line 1887, in upsert_sweep
    raise (e)
  File "/home/kevinteng/envs/tfenv/lib/python3.6/site-packages/wandb/sdk/internal/internal_api.py", line 1884, in upsert_sweep
    check_retry_fn=no_retry_4xx,
  File "/home/kevinteng/envs/tfenv/lib/python3.6/site-packages/wandb/sdk/lib/retry.py", line 118, in __call__
    if not check_retry_fn(e):
  File "/home/kevinteng/envs/tfenv/lib/python3.6/site-packages/wandb/sdk/internal/internal_api.py", line 1864, in no_retry_4xx
    raise UsageError(body["errors"][0]["message"])
wandb.errors.UsageError: Invalid sweep config: invalid hyperparameter configuration: learning_rate

During handling of the above exception, another exception occurred:

Traceback (most recent call last):
  File "/home/kevinteng/envs/tfenv/lib/python3.6/site-packages/wandb/cli/cli.py", line 86, in wrapper
    return func(*args, **kwargs)
  File "/home/kevinteng/envs/tfenv/lib/python3.6/site-packages/wandb/cli/cli.py", line 858, in sweep
    config, project=project, entity=entity, obj_id=sweep_obj_id
  File "/home/kevinteng/envs/tfenv/lib/python3.6/site-packages/wandb/apis/internal.py", line 99, in upsert_sweep
    return self.api.upsert_sweep(*args, **kwargs)
  File "/home/kevinteng/envs/tfenv/lib/python3.6/site-packages/wandb/apis/normalize.py", line 62, in wrapper
    six.reraise(CommError, CommError(message, err), sys.exc_info()[2])
  File "/home/kevinteng/envs/tfenv/lib/python3.6/site-packages/six.py", line 718, in reraise
    raise value.with_traceback(tb)
  File "/home/kevinteng/envs/tfenv/lib/python3.6/site-packages/wandb/apis/normalize.py", line 24, in wrapper
    return func(*args, **kwargs)
  File "/home/kevinteng/envs/tfenv/lib/python3.6/site-packages/wandb/sdk/internal/internal_api.py", line 1887, in upsert_sweep
    raise (e)
  File "/home/kevinteng/envs/tfenv/lib/python3.6/site-packages/wandb/sdk/internal/internal_api.py", line 1884, in upsert_sweep
    check_retry_fn=no_retry_4xx,
  File "/home/kevinteng/envs/tfenv/lib/python3.6/site-packages/wandb/sdk/lib/retry.py", line 118, in __call__
    if not check_retry_fn(e):
  File "/home/kevinteng/envs/tfenv/lib/python3.6/site-packages/wandb/sdk/internal/internal_api.py", line 1864, in no_retry_4xx
    raise UsageError(body["errors"][0]["message"])
wandb.errors.CommError: Invalid sweep config: invalid hyperparameter configuration: learning_rate

2022-03-18 18:34:35 ERROR 400 response executing GraphQL.
2022-03-18 18:34:35 ERROR {"errors":[{"message":"Invalid sweep config: invalid hyperparameter configuration: learning_rate","path":["upsertSweep"]}],"data":{"upsertSweep":null}}
2022-03-18 18:34:35 ERROR Traceback (most recent call last):
  File "/home/kevinteng/envs/tfenv/lib/python3.6/site-packages/wandb/sdk/lib/retry.py", line 102, in __call__
    result = self._call_fn(*args, **kwargs)
  File "/home/kevinteng/envs/tfenv/lib/python3.6/site-packages/wandb/sdk/internal/internal_api.py", line 146, in execute
    six.reraise(*sys.exc_info())
  File "/home/kevinteng/envs/tfenv/lib/python3.6/site-packages/six.py", line 719, in reraise
    raise value
  File "/home/kevinteng/envs/tfenv/lib/python3.6/site-packages/wandb/sdk/internal/internal_api.py", line 140, in execute
    return self.client.execute(*args, **kwargs)
  File "/home/kevinteng/envs/tfenv/lib/python3.6/site-packages/wandb/vendor/gql-0.2.0/wandb_gql/client.py", line 52, in execute
    result = self._get_result(document, *args, **kwargs)
  File "/home/kevinteng/envs/tfenv/lib/python3.6/site-packages/wandb/vendor/gql-0.2.0/wandb_gql/client.py", line 60, in _get_result
    return self.transport.execute(document, *args, **kwargs)
  File "/home/kevinteng/envs/tfenv/lib/python3.6/site-packages/wandb/vendor/gql-0.2.0/wandb_gql/transport/requests.py", line 39, in execute
    request.raise_for_status()
  File "/home/kevinteng/envs/tfenv/lib/python3.6/site-packages/requests/models.py", line 943, in raise_for_status
    raise HTTPError(http_error_msg, response=self)
requests.exceptions.HTTPError: 400 Client Error: Bad Request for url: https://api.wandb.ai/graphql

During handling of the above exception, another exception occurred:

Traceback (most recent call last):
  File "/home/kevinteng/envs/tfenv/lib/python3.6/site-packages/wandb/apis/normalize.py", line 24, in wrapper
    return func(*args, **kwargs)
  File "/home/kevinteng/envs/tfenv/lib/python3.6/site-packages/wandb/sdk/internal/internal_api.py", line 1887, in upsert_sweep
    raise (e)
  File "/home/kevinteng/envs/tfenv/lib/python3.6/site-packages/wandb/sdk/internal/internal_api.py", line 1884, in upsert_sweep
    check_retry_fn=no_retry_4xx,
  File "/home/kevinteng/envs/tfenv/lib/python3.6/site-packages/wandb/sdk/lib/retry.py", line 118, in __call__
    if not check_retry_fn(e):
  File "/home/kevinteng/envs/tfenv/lib/python3.6/site-packages/wandb/sdk/internal/internal_api.py", line 1864, in no_retry_4xx
    raise UsageError(body["errors"][0]["message"])
wandb.errors.UsageError: Invalid sweep config: invalid hyperparameter configuration: learning_rate

During handling of the above exception, another exception occurred:

Traceback (most recent call last):
  File "/home/kevinteng/envs/tfenv/lib/python3.6/site-packages/wandb/cli/cli.py", line 86, in wrapper
    return func(*args, **kwargs)
  File "/home/kevinteng/envs/tfenv/lib/python3.6/site-packages/wandb/cli/cli.py", line 858, in sweep
    config, project=project, entity=entity, obj_id=sweep_obj_id
  File "/home/kevinteng/envs/tfenv/lib/python3.6/site-packages/wandb/apis/internal.py", line 99, in upsert_sweep
    return self.api.upsert_sweep(*args, **kwargs)
  File "/home/kevinteng/envs/tfenv/lib/python3.6/site-packages/wandb/apis/normalize.py", line 62, in wrapper
    six.reraise(CommError, CommError(message, err), sys.exc_info()[2])
  File "/home/kevinteng/envs/tfenv/lib/python3.6/site-packages/six.py", line 718, in reraise
    raise value.with_traceback(tb)
  File "/home/kevinteng/envs/tfenv/lib/python3.6/site-packages/wandb/apis/normalize.py", line 24, in wrapper
    return func(*args, **kwargs)
  File "/home/kevinteng/envs/tfenv/lib/python3.6/site-packages/wandb/sdk/internal/internal_api.py", line 1887, in upsert_sweep
    raise (e)
  File "/home/kevinteng/envs/tfenv/lib/python3.6/site-packages/wandb/sdk/internal/internal_api.py", line 1884, in upsert_sweep
    check_retry_fn=no_retry_4xx,
  File "/home/kevinteng/envs/tfenv/lib/python3.6/site-packages/wandb/sdk/lib/retry.py", line 118, in __call__
    if not check_retry_fn(e):
  File "/home/kevinteng/envs/tfenv/lib/python3.6/site-packages/wandb/sdk/internal/internal_api.py", line 1864, in no_retry_4xx
    raise UsageError(body["errors"][0]["message"])
wandb.errors.CommError: Invalid sweep config: invalid hyperparameter configuration: learning_rate

2022-03-18 18:35:11 INFO Running runs: []
2022-03-18 18:35:12 INFO Agent received command: run
2022-03-18 18:35:12 INFO Agent starting run with config:
	aug_prob: 0.5
	batch_size: 4
	csv: data.csv
	encoder_model: resnet50
	epochs: 200
	learning_rate: 0.01
	n_class: 1
	optimizer: torch.optim.Adam
	patch_size: (512, 512)
2022-03-18 18:35:12 INFO About to run command: /usr/bin/env python train.py --aug_prob=0.5 --batch_size=4 --csv=data.csv --encoder_model=resnet50 --epochs=200 --learning_rate=0.01 --n_class=1 --optimizer=torch.optim.Adam "--patch_size=(512, 512)"
2022-03-18 18:35:17 INFO Running runs: ['5pf3jpw4']
